[2024-09-21T10:46:32.684+0000] {taskinstance.py:1087} INFO - Dependencies all met for <TaskInstance: dag_saver_v01.fetch_vk_data manual__2024-09-21T10:41:26.018213+00:00 [queued]>
[2024-09-21T10:46:32.697+0000] {taskinstance.py:1087} INFO - Dependencies all met for <TaskInstance: dag_saver_v01.fetch_vk_data manual__2024-09-21T10:41:26.018213+00:00 [queued]>
[2024-09-21T10:46:32.697+0000] {taskinstance.py:1283} INFO - 
--------------------------------------------------------------------------------
[2024-09-21T10:46:32.697+0000] {taskinstance.py:1284} INFO - Starting attempt 1 of 2
[2024-09-21T10:46:32.697+0000] {taskinstance.py:1285} INFO - 
--------------------------------------------------------------------------------
[2024-09-21T10:46:32.709+0000] {taskinstance.py:1304} INFO - Executing <Task(PythonOperator): fetch_vk_data> on 2024-09-21 10:41:26.018213+00:00
[2024-09-21T10:46:32.717+0000] {standard_task_runner.py:55} INFO - Started process 6031 to run task
[2024-09-21T10:46:32.722+0000] {standard_task_runner.py:82} INFO - Running: ['***', 'tasks', 'run', 'dag_saver_v01', 'fetch_vk_data', 'manual__2024-09-21T10:41:26.018213+00:00', '--job-id', '22', '--raw', '--subdir', 'DAGS_FOLDER/dag_saver.py', '--cfg-path', '/tmp/tmp_brco1sj']
[2024-09-21T10:46:32.723+0000] {standard_task_runner.py:83} INFO - Job 22: Subtask fetch_vk_data
[2024-09-21T10:46:32.802+0000] {task_command.py:389} INFO - Running <TaskInstance: dag_saver_v01.fetch_vk_data manual__2024-09-21T10:41:26.018213+00:00 [running]> on host 16da3808dee2
[2024-09-21T10:46:32.861+0000] {taskinstance.py:1513} INFO - Exporting the following env vars:
AIRFLOW_CTX_DAG_OWNER=<NAME>
AIRFLOW_CTX_DAG_ID=dag_saver_v01
AIRFLOW_CTX_TASK_ID=fetch_vk_data
AIRFLOW_CTX_EXECUTION_DATE=2024-09-21T10:41:26.018213+00:00
AIRFLOW_CTX_TRY_NUMBER=1
AIRFLOW_CTX_DAG_RUN_ID=manual__2024-09-21T10:41:26.018213+00:00
[2024-09-21T10:46:33.280+0000] {taskinstance.py:1772} ERROR - Task failed with exception
Traceback (most recent call last):
  File "/home/airflow/.local/lib/python3.7/site-packages/airflow/operators/python.py", line 175, in execute
    return_value = self.execute_callable()
  File "/home/airflow/.local/lib/python3.7/site-packages/airflow/operators/python.py", line 192, in execute_callable
    return self.python_callable(*self.op_args, **self.op_kwargs)
  File "/opt/airflow/dags/scripts/fetch_data_vk.py", line 5, in fetch_data
    result = wall_get(domain=link, serv_key=token, count_posts=1)
  File "/opt/airflow/dags/scripts/fetch_data_vk.py", line 16, in wall_get
    q = resp.json()['response']['items']
KeyError: 'response'
[2024-09-21T10:46:33.297+0000] {taskinstance.py:1327} INFO - Marking task as UP_FOR_RETRY. dag_id=dag_saver_v01, task_id=fetch_vk_data, execution_date=20240921T104126, start_date=20240921T104632, end_date=20240921T104633
[2024-09-21T10:46:33.312+0000] {standard_task_runner.py:105} ERROR - Failed to execute job 22 for task fetch_vk_data ('response'; 6031)
[2024-09-21T10:46:33.335+0000] {local_task_job.py:159} INFO - Task exited with return code 1
[2024-09-21T10:46:33.405+0000] {taskinstance.py:2582} INFO - 0 downstream tasks scheduled from follow-on schedule check
